Traceback (most recent call last):
  File "gen_num_mi_feat_target.py", line 7, in <module>
    df = pk.load(f)
IOError: [Errno 9] Bad file descriptor
